Workbook

Sheet Donnees figees
A1: Investissement
A2: Nom de l'entreprise
A3: Promoteur
A4: Année création
A5: Secteur
A6: Ville
A7: Stade de développement
A8: Année investissement
A9: Méthode de valorisation à l'acquisition
A10: Date sortie attendue
A11: Multiple sortie
A12: Scénario sortie
... A29: Prêt 2
A30: Taux | B30: 0.1
A31: Taux variable
A32: Décaissement 1 : montant
A33: Décaissement 1 : date
A34: Décaissement 2 : montant
A35: Décaissement 2 : date
A36: Décaissement 3 : montant
A37: Décaissement 3 : date
A38: Décaissement 4 : montant
A39: Décaissement 4 : date
A40: Décaissement 5 : montant
A41: Décaissement 5 : date
A43: Prêt 3
... A71: Données impact à l'entrée ?

Sheet Capital
A1: PARAMETRES | D1: 1 | E1: 42185 | F1: 42277 | G1: 42369 | H1: 42460 | I1: 42551 | J1: 42643 | K1: 42735 | L1: 42825 | M1: 42916 | N1: 43008 | O1: 43100 | P1: 43190 | Q1: 43281 | R1: 43373 | S1: 43465 | T1: 43555 | U1: 43646 | V1: 43738 | W1: 43830 | X1: 43921 | Y1: 44012 | Z1: 44104 | AA1: 44196 | AB1: 44286 | AC1: 44377 | AD1: 44469 | AE1: 44561
A2: EQUITY | D2: 2 | E2: 1 | F2: 2 | G2: 3 | H2: 4 | I2: 5 | J2: 6 | K2: 7 | L2: 8 | M2: 9 | N2: 10 | O2: 11 | P2: 12 | Q2: 13 | R2: 14 | S2: 15 | T2: 16 | U2: 17 | V2: 18 | W2: 19 | X2: 20 | Y2: 21 | Z2: 22 | AA2: 23 | AB2: 24 | AC2: 25 | AD2: 26 | AE2: 27
D3: 3
A4: FLUX | B4: Realise | C4: Engagement | D4: 4
A5: FLUX | B5: Realise | C5: Décaissements | D5: 5
A6: FLUX | B6: Realise | C6: Conversion (de prêts, arriérés) | D6: 6
A7: FLUX | B7: Realise | C7: Encaissement (remboursement du coût historique des actions) | D7: 7
A8: FLUX | B8: Realise | C8: Encaissement (plus ou moins value sur les actions cédées) | D8: 8
A9: FLUX | B9: Realise | C9: Revalorisations latentes | D9: 9
A10: FLUX | B10: Realise | C10: Autres revenus encaissés (dividendes, commission montage) | D10: 10
A11: FLUX | B11: Realise | C11: % détention | D11: 11
D12: 12
D13: 13
A14: STOCK | B14: Realise | C14: Total engagé | D14: 14 | E14: =+E4 -> 0 | F14: =+SUM($E4:F$4) -> 0 | G14: =+SUM($E4:G$4) -> 0 | H14: =+SUM($E4:H$4) -> 0 | I14: =+SUM($E4:I$4) -> 0 | J14: =+SUM($E4:J$4) -> 0 | K14: =+SUM($E4:K$4) -> 0 | L14: =+SUM($E4:L$4) -> 0 | M14: =+SUM($E4:M$4) -> 0 | ... AE14: =+SUM($E4:AE$4) -> 0
A15: STOCK | B15: Realise | C15: Coût historique | D15: 15 | E15: =E5 -> 0 | F15: =+E15+SUM(F5:F6)-F7 -> 0 | G15: =+F15+SUM(G5:G6)-G7 -> 0 | H15: =+G15+SUM(H5:H6)-H7 -> 0 | I15: =+H15+SUM(I5:I6)-I7 -> 0 | J15: =+I15+SUM(J5:J6)-J7 -> 0 | K15: =+J15+SUM(K5:K6)-K7 -> 0 | L15: =+K15+SUM(L5:L6)-L7 -> 0 | M15: =+L15+SUM(M5:M6)-M7 -> 0 | ... AE15: =+AD15+SUM(AE5:AE6)-AE7 -> 0
A16: STOCK | B16: Realise | C16: Valorisation | D16: 16 | E16: =+E15 -> 0 | F16: =+E16+F5+F6-F7-F8+F9 -> 0 | G16: =+F16+G5+G6-G7-G8+G9 -> 0 | H16: =+G16+H5+H6-H7-H8+H9 -> 0 | I16: =+H16+I5+I6-I7-I8+I9 -> 0 | J16: =+I16+J5+J6-J7-J8+J9 -> 0 | K16: =+J16+K5+K6-K7-K8+K9 -> 0 | L16: =+K16+L5+L6-L7-L8+L9 -> 0 | M16: =+L16+M5+M6-M7-M8+M9 -> 0 | ... AE16: =+AD16+AE5+AE6-AE7-AE8+AE9 -> 0
A17: STOCK | B17: Realise | C17: Total décaissé | D17: 17 | E17: =+E5+E6 -> 0 | F17: =+SUM($E$5:F6) -> 0 | G17: =+SUM($E$5:G6) -> 0 | H17: =+SUM($E$5:H6) -> 0 | I17: =+SUM($E$5:I6) -> 0 | J17: =+SUM($E$5:J6) -> 0 | K17: =+SUM($E$5:K6) -> 0 | L17: =+SUM($E$5:L6) -> 0 | M17: =+SUM($E$5:M6) -> 0 | ... AE17: =+SUM($E$5:AE6) -> 0
A18: STOCK | B18: Realise | C18: Total remboursements capital | D18: 18 | E18: =+E7 -> 0 | F18: =+SUM($E$7:F7) -> 0 | G18: =+SUM($E$7:G7) -> 0 | H18: =+SUM($E$7:H7) -> 0 | I18: =+SUM($E$7:I7) -> 0 | J18: =+SUM($E$7:J7) -> 0 | K18: =+SUM($E$7:K7) -> 0 | L18: =+SUM($E$7:L7) -> 0 | M18: =+SUM($E$7:M7) -> 0 | ... AE18: =+SUM($E$7:AE7) -> 0
A19: STOCK | B19: Realise | C19: Total plus-values encaissées | D19: 19 | E19: =+E8 -> 0 | F19: =+SUM($E$8:F8) -> 0 | G19: =+SUM($E$8:G8) -> 0 | H19: =+SUM($E$8:H8) -> 0 | I19: =+SUM($E$8:I8) -> 0 | J19: =+SUM($E$8:J8) -> 0 | K19: =+SUM($E$8:K8) -> 0 | L19: =+SUM($E$8:L8) -> 0 | M19: =+SUM($E$8:M8) -> 0 | ... AE19: =+SUM($E$8:AE8) -> 0
A20: STOCK | B20: Realise | C20: Total Revalorisation | D20: 20 | E20: =+E9 -> 0 | F20: =+SUM($E$9:F9) -> 0 | G20: =+SUM($E$9:G9) -> 0 | H20: =+SUM($E$9:H9) -> 0 | I20: =+SUM($E$9:I9) -> 0 | J20: =+SUM($E$9:J9) -> 0 | K20: =+SUM($E$9:K9) -> 0 | L20: =+SUM($E$9:L9) -> 0 | M20: =+SUM($E$9:M9) -> 0 | ... AE20: =+SUM($E$9:AE9) -> 0
A21: STOCK | B21: Realise | C21: Total Autres revenus encaissés | D21: 21 | E21: =+E10 -> 0 | F21: =+SUM($E$10:F10) -> 0 | G21: =+SUM($E$10:G10) -> 0 | H21: =+SUM($E$10:H10) -> 0 | I21: =+SUM($E$10:I10) -> 0 | J21: =+SUM($E$10:J10) -> 0 | K21: =+SUM($E$10:K10) -> 0 | L21: =+SUM($E$10:L10) -> 0 | M21: =+SUM($E$10:M10) -> 0 | ... AE21: =+SUM($E$10:AE10) -> 0
D22: 22
D23: 23
D24: 24
D25: 25
D26: 26
D27: 27
D28: 28
D29: 29
D30: 30
D31: 31
D32: 32
D33: 33
D34: 34

Sheet Pret
A1: PARAMETRES | D1: 1 | E1: 42185 | F1: 42277 | G1: 42369 | H1: 42460 | I1: 42551 | J1: 42643 | K1: 42735 | L1: 42825 | M1: 42916 | N1: 43008 | O1: 43100 | P1: 43190 | Q1: 43281 | R1: 43373 | S1: 43465 | T1: 43555 | U1: 43646 | V1: 43738 | W1: 43830 | X1: 43921 | Y1: 44012 | Z1: 44104 | AA1: 44196 | AB1: 44286 | AC1: 44377 | AD1: 44469 | AE1: 44561
A2: PRET | D2: 2 | E2: 1 | F2: 2 | G2: 3 | H2: 4 | I2: 5 | J2: 6 | K2: 7 | L2: 8 | M2: 9 | N2: 10 | O2: 11 | P2: 12 | Q2: 13 | R2: 14 | S2: 15 | T2: 16 | U2: 17 | V2: 18 | W2: 19 | X2: 20 | Y2: 21 | Z2: 22 | AA2: 23 | AB2: 24 | AC2: 25 | AD2: 26 | AE2: 27
D3: 3
A4: FLUX | B4: Realise | C4: Engagement | D4: 4
A5: FLUX | B5: Realise | C5: Décaissements | D5: 5
A6: FLUX | B6: Realise | C6: Capitalisation d'arriérés (intérêts et principal) | D6: 6
D7: 7
A8: FLUX | B8: Theorique | C8: Principal remboursé - facturé / prévisions | D8: 8
A9: FLUX | B9: Realise | C9: Principal remboursé - encaissé | D9: 9
A10: FLUX | B10: Realise | C10: Principal remboursé - converti / capitalisé | D10: 10
D11: 11
A12: FLUX | B12: Theorique | C12: Intérêts - facturé / prévisions | D12: 12
A13: FLUX | B13: Realise | C13: Intérêts - encaissé | D13: 13
A14: FLUX | B14: Realise | C14: Intérêts - converti / Capitalisé | D14: 14
D15: 15
A16: FLUX | B16: Realise | C16: Provision (-) /reprise (+) | D16: 16
A17: FLUX | B17: Realise | C17: Provision sur arriérés principal | D17: 17
A18: FLUX | B18: Realise | C18: Provision sur arriérés intérêts | D18: 18
D19: 19
A20: FLUX | B20: Realise | C20: Moins-value constatée (-) | D20: 20
D21: 21
D22: 22
A23: STOCK | B23: Realise | C23: Total engagé | D23: 23 | E23: =+E4 -> 0 | F23: =+SUM($E$4:F4) -> 0 | G23: =+SUM($E$4:G4) -> 0 | H23: =+SUM($E$4:H4) -> 0 | I23: =+SUM($E$4:I4) -> 0 | J23: =+SUM($E$4:J4) -> 0 | K23: =+SUM($E$4:K4) -> 0 | L23: =+SUM($E$4:L4) -> 0 | M23: =+SUM($E$4:M4) -> 0 | ... AE23: =+SUM($E$4:AE4) -> 0
A24: STOCK | B24: Realise | C24: Total décaissé | D24: 24 | E24: =+E5 -> 0 | F24: =+SUM($E$5:F5) -> 0 | G24: =+SUM($E$5:G5) -> 0 | H24: =+SUM($E$5:H5) -> 0 | I24: =+SUM($E$5:I5) -> 0 | J24: =+SUM($E$5:J5) -> 0 | K24: =+SUM($E$5:K5) -> 0 | L24: =+SUM($E$5:L5) -> 0 | M24: =+SUM($E$5:M5) -> 0 | ... AE24: =+SUM($E$5:AE5) -> 0
A25: STOCK | B25: Realise | C25: Total reboursements | D25: 25 | E25: =+E9 -> 0 | F25: =+SUM($E$9:F9) -> 0 | G25: =+SUM($E$9:G9) -> 0 | H25: =+SUM($E$9:H9) -> 0 | I25: =+SUM($E$9:I9) -> 0 | J25: =+SUM($E$9:J9) -> 0 | K25: =+SUM($E$9:K9) -> 0 | L25: =+SUM($E$9:L9) -> 0 | M25: =+SUM($E$9:M9) -> 0 | ... AE25: =+SUM($E$9:AE9) -> 0
A26: STOCK | B26: Realise | C26: Total intérêts | D26: 26 | E26: =+E13 -> 0 | F26: =+SUM($E$13:F13) -> 0 | G26: =+SUM($E$13:G13) -> 0 | H26: =+SUM($E$13:H13) -> 0 | I26: =+SUM($E$13:I13) -> 0 | J26: =+SUM($E$13:J13) -> 0 | K26: =+SUM($E$13:K13) -> 0 | L26: =+SUM($E$13:L13) -> 0 | M26: =+SUM($E$13:M13) -> 0 | ... AE26: =+SUM($E$13:AE13) -> 0
D27: 27
A28: STOCK | B28: Theorique | C28: Encours comptable / prévision | D28: 28 | E28: =+E5+E6 -> 0 | F28: =+E28+F5+F6-F8 -> 0 | G28: =+F28+G5+G6-G8 -> 0 | H28: =+G28+H5+H6-H8 -> 0 | I28: =+H28+I5+I6-I8 -> 0 | J28: =+I28+J5+J6-J8 -> 0 | K28: =+J28+K5+K6-K8 -> 0 | L28: =+K28+L5+L6-L8 -> 0 | M28: =+L28+M5+M6-M8 -> 0 | ... AE28: =+AD28+AE5+AE6-AE8 -> 0
A29: STOCK | B29: Realise | C29: Encours - cash | D29: 29 | E29: =+E5+E6 -> 0 | F29: =+E29+F5+F6-F9-F10 -> 0 | G29: =+F29+G5+G6-G9-G10 -> 0 | H29: =+G29+H5+H6-H9-H10 -> 0 | I29: =+H29+I5+I6-I9-I10 -> 0 | J29: =+I29+J5+J6-J9-J10 -> 0 | K29: =+J29+K5+K6-K9-K10 -> 0 | L29: =+K29+L5+L6-L9-L10 -> 0 | M29: =+L29+M5+M6-M9-M10 -> 0 | ... AE29: =+AD29+AE5+AE6-AE9-AE10 -> 0
D30: 30
A31: STOCK | B31: Realise | C31: Valo - comptable | D31: 31 | E31: =+E28+E16 -> 0 | F31: =+F28+F16 -> 0 | G31: =+G28+G16 -> 0 | H31: =+H28+H16 -> 0 | I31: =+I28+I16 -> 0 | J31: =+J28+J16 -> 0 | K31: =+K28+K16 -> 0 | L31: =+L28+L16 -> 0 | ... AE31: =+AE28+AE16 -> 0
D32: 32
A33: STOCK | B33: Realise | C33: Arriérés principal | D33: 33 | E33: =+E8-E9-E10 -> 0 | F33: =+SUM($E$8:F8)-SUM($E$9:F10) -> 0 | G33: =+SUM($E$8:G8)-SUM($E$9:G10) -> 0 | H33: =+SUM($E$8:H8)-SUM($E$9:H10) -> 0 | I33: =+SUM($E$8:I8)-SUM($E$9:I10) -> 0 | J33: =+SUM($E$8:J8)-SUM($E$9:J10) -> 0 | K33: =+SUM($E$8:K8)-SUM($E$9:K10) -> 0 | L33: =+SUM($E$8:L8)-SUM($E$9:L10) -> 0 | M33: =+SUM($E$8:M8)-SUM($E$9:M10) -> 0 | ... AE33: =+SUM($E$8:AE8)-SUM($E$9:AE10) -> 0
A34: STOCK | B34: Realise | C34: Arriérés intérêts | D34: 34 | E34: =+E12-E13-E14 -> 0 | F34: =+SUM($E$12:F12)-SUM($E$13:F14) -> 0 | G34: =+SUM($E$12:G12)-SUM($E$13:G14) -> 0 | H34: =+SUM($E$12:H12)-SUM($E$13:H14) -> 0 | I34: =+SUM($E$12:I12)-SUM($E$13:I14) -> 0 | J34: =+SUM($E$12:J12)-SUM($E$13:J14) -> 0 | K34: =+SUM($E$12:K12)-SUM($E$13:K14) -> 0 | L34: =+SUM($E$12:L12)-SUM($E$13:L14) -> 0 | M34: =+SUM($E$12:M12)-SUM($E$13:M14) -> 0 | ... AE34: =+SUM($E$12:AE12)-SUM($E$13:AE14) -> 0
D35: 35
A36: STOCK | B36: Realise | C36: Arriérés principal - valo | D36: 36 | E36: =+E8-E9-E10+E17 -> 0 | F36: =+SUM($E$8:F8)-SUM($E$9:F10)-SUM($E$17:F17) -> 0 | G36: =+SUM($E$8:G8)-SUM($E$9:G10)-SUM($E$17:G17) -> 0 | H36: =+SUM($E$8:H8)-SUM($E$9:H10)-SUM($E$17:H17) -> 0 | I36: =+SUM($E$8:I8)-SUM($E$9:I10)-SUM($E$17:I17) -> 0 | J36: =+SUM($E$8:J8)-SUM($E$9:J10)-SUM($E$17:J17) -> 0 | K36: =+SUM($E$8:K8)-SUM($E$9:K10)-SUM($E$17:K17) -> 0 | L36: =+SUM($E$8:L8)-SUM($E$9:L10)-SUM($E$17:L17) -> 0 | M36: =+SUM($E$8:M8)-SUM($E$9:M10)-SUM($E$17:M17) -> 0 | ... AE36: =+SUM($E$8:AE8)-SUM($E$9:AE10)-SUM($E$17:AE17) -> 0
A37: STOCK | B37: Realise | C37: Arriérés intérêts - valo | D37: 37 | E37: =+E12-E13-E14+E18 -> 0 | F37: =+SUM($E$12:F12)-SUM($E$13:F14)-SUM($E$18:F18) -> 0 | G37: =+SUM($E$12:G12)-SUM($E$13:G14)-SUM($E$18:G18) -> 0 | H37: =+SUM($E$12:H12)-SUM($E$13:H14)-SUM($E$18:H18) -> 0 | I37: =+SUM($E$12:I12)-SUM($E$13:I14)-SUM($E$18:I18) -> 0 | J37: =+SUM($E$12:J12)-SUM($E$13:J14)-SUM($E$18:J18) -> 0 | K37: =+SUM($E$12:K12)-SUM($E$13:K14)-SUM($E$18:K18) -> 0 | L37: =+SUM($E$12:L12)-SUM($E$13:L14)-SUM($E$18:L18) -> 0 | M37: =+SUM($E$12:M12)-SUM($E$13:M14)-SUM($E$18:M18) -> 0 | ... AE37: =+SUM($E$12:AE12)-SUM($E$13:AE14)-SUM($E$18:AE18) -> 0
D38: 38
D39: 39
D40: 40

Sheet Performance
A1: PARAMETRES | D1: 1 | E1: 42185 | F1: 42277 | G1: 42369 | H1: 42460 | I1: 42551 | J1: 42643 | K1: 42735 | L1: 42825 | M1: 42916 | N1: 43008 | O1: 43100 | P1: 43190 | Q1: 43281 | R1: 43373 | S1: 43465 | T1: 43555 | U1: 43646 | V1: 43738 | W1: 43830 | X1: 43921 | Y1: 44012 | Z1: 44104 | AA1: 44196 | AB1: 44286 | AC1: 44377 | AD1: 44469 | AE1: 44561
A2: PERFORMANCE | D2: 2 | E2: 1 | F2: 2 | G2: 3 | H2: 4 | I2: 5 | J2: 6 | K2: 7 | L2: 8 | M2: 9 | N2: 10 | O2: 11 | P2: 12 | Q2: 13 | R2: 14 | S2: 15 | T2: 16 | U2: 17 | V2: 18 | W2: 19 | X2: 20 | Y2: 21 | Z2: 22 | AA2: 23 | AB2: 24 | AC2: 25 | AD2: 26 | AE2: 27
D3: 3
A4: STOCK | B4: P&L | C4: CA | D4: 4
A5: STOCK | B5: P&L | C5: Marge brute | D5: 5
A6: STOCK | B6: P&L | C6: EBE | D6: 6
A7: STOCK | B7: P&L | C7: RN | D7: 7
D8: 8
D9: 9
A10: STOCK | B10: Actif | C10: Immobilisations | D10: 10
A11: STOCK | B11: Actif | C11: Actif circulant | D11: 11
A12: STOCK | B12: Actif | C12: Trésorerie | D12: 12
D13: 13
A14: STOCK | B14: Passif | C14: Fonds propres | D14: 14
A15: STOCK | B15: Passif | C15: Dettes long terme | D15: 15
A16: STOCK | B16: Passif | C16: Dettes court terme | D16: 16
D17: 17
D18: 18
A19: STOCK | B19: Notes internes | C19: Performance Financière | D19: 19
A20: STOCK | B20: Notes internes | C20: Performance Organisationelle | D20: 20
D21: 21
D22: 22
D23: 23
D24: 24

Sheet Impact
A1: PARAMETRES | D1: 1 | E1: 42185 | F1: 42277 | G1: 42369 | H1: 42460 | I1: 42551 | J1: 42643 | K1: 42735 | L1: 42825 | M1: 42916 | N1: 43008 | O1: 43100 | P1: 43190 | Q1: 43281 | R1: 43373 | S1: 43465 | T1: 43555 | U1: 43646 | V1: 43738 | W1: 43830 | X1: 43921 | Y1: 44012 | Z1: 44104 | AA1: 44196 | AB1: 44286 | AC1: 44377 | AD1: 44469 | AE1: 44561
A2: IMPACT | D2: 2 | E2: 1 | F2: 2 | G2: 3 | H2: 4 | I2: 5 | J2: 6 | K2: 7 | L2: 8 | M2: 9 | N2: 10 | O2: 11 | P2: 12 | Q2: 13 | R2: 14 | S2: 15 | T2: 16 | U2: 17 | V2: 18 | W2: 19 | X2: 20 | Y2: 21 | Z2: 22 | AA2: 23 | AB2: 24 | AC2: 25 | AD2: 26 | AE2: 27
D3: 3
B4: Employés | C4: Emplois formels temps plein Hommes | D4: 4
B5: Employés | C5: Emplois formels temps partiel Hommes | D5: 5
B6: Employés | C6: Emplois informels temps plein Hommes | D6: 6
B7: Employés | C7: Emplois informels temps partiel Hommes | D7: 7
B8: Employés | C8: Emplois formels temps plein Femmes | D8: 8
B9: Employés | C9: Emplois formels temps partiel Femmes | D9: 9
B10: Employés | C10: Emplois informels temps plein Femmes | D10: 10
B11: Employés | C11: Emplois informels temps partiel Femmes | D11: 11
B12: Employés | C12: Emplois saisonniers | D12: 12
B13: Employés | C13: Nombres emplois | D13: 13 | E13: =+SUM(E4:E11) -> 0 | F13: =+SUM(F4:F11) -> 0 | G13: =+SUM(G4:G11) -> 0 | H13: =+SUM(H4:H11) -> 0 | I13: =+SUM(I4:I11) -> 0 | J13: =+SUM(J4:J11) -> 0 | K13: =+SUM(K4:K11) -> 0 | L13: =+K13 -> 0 | M13: =+SUM(M4:M11) -> 0 | N13: =+SUM(N4:N11) -> 0 | O13: =+SUM(O4:O11) -> 0 | P13: =+SUM(P4:P11) -> 0 | Q13: =+SUM(Q4:Q11) -> 0 | R13: =+SUM(R4:R11) -> 0 | S13: =+SUM(S4:S11) -> 0 | T13: =+SUM(T4:T11) -> 0 | ... AE13: =+SUM(AE4:AE11) -> 0
D14: 14
B15: Formalisation | C15: Employés formalisés | D15: 15
D16: 16
B17: Turn-over | C17: Employés à temps plein ayant quitté l'entreprise | D17: 17
D18: 18
B19: Qualification | C19: % d'employés faiblement qualifiés (approximation possible) | D19: 19
B20: Qualification | C20: % d'employés moyennement qualifiés (approximation possible) | D20: 20
B21: Qualification | C21: % d'employés très qualifiés (approximation possible) | D21: 21
B22: Qualification | C22: % de femmes parmi les employés très qualifiés | D22: 22
B23: Qualification | C23: % d'employés qui ont moins de 25 ans | D23: 23
D24: 24
B25: Formation | C25: Nombre d'employés formés | D25: 25
B26: Formation | C26: Coûts formation | D26: 26
D27: 27
B28: Rémunération | C28: Masse salariale annuelle brute | D28: 28
B29: Rémunération | C29: Salaire net minimum en vigueur dans le pays | D29: 29
B30: Rémunération | C30: Salaire net minimum d'un employé formel | D30: 30
D31: 31
B32: Sécurité Sociale | C32: Employés affiliés caisse de sécurité sociale | D32: 32
B33: Sécurité Sociale | C33: Employés disposant assurance/mutuelle santé privée | D33: 33
B34: Sécurité Sociale | C34: Nombre accidents du travail | D34: 34
D35: 35
B36: Clients Fournisseurs | C36: Quantité achetées | D36: 36
B37: Clients Fournisseurs | C37: Nombre petits fournisseurs | D37: 37
B38: Clients Fournisseurs | C38: Nombre petits distributeurs | D38: 38
B39: Clients Fournisseurs | C39: Nombre clients finaux | D39: 39
B40: Clients Fournisseurs | C40: Nombre bénéficiaires programme accompagnement | D40: 40
...

Sheet Couts suivi
A1: PARAMETRES | D1: 1 | E1: 42185 | F1: 42277 | G1: 42369 | H1: 42460 | I1: 42551 | J1: 42643 | K1: 42735 | L1: 42825 | M1: 42916 | N1: 43008 | O1: 43100 | P1: 43190 | Q1: 43281 | R1: 43373 | S1: 43465 | T1: 43555 | U1: 43646 | V1: 43738 | W1: 43830 | X1: 43921 | Y1: 44012 | Z1: 44104 | AA1: 44196 | AB1: 44286 | AC1: 44377 | AD1: 44469 | AE1: 44561
A2: COUTS | D2: 2 | E2: 1 | F2: 2 | G2: 3 | H2: 4 | I2: 5 | J2: 6 | K2: 7 | L2: 8 | M2: 9 | N2: 10 | O2: 11 | P2: 12 | Q2: 13 | R2: 14 | S2: 15 | T2: 16 | U2: 17 | V2: 18 | W2: 19 | X2: 20 | Y2: 21 | Z2: 22 | AA2: 23 | AB2: 24 | AC2: 25 | AD2: 26 | AE2: 27
D3: 3
A4: FLUX | B4: Realise | C4: Charges salariales | D4: 4
A5: FLUX | B5: Realise | C5: Charges variables | D5: 5
A6: FLUX | B6: Realise | C6: Fonctions support | D6: 6
A7: FLUX | B7: Realise | C7: Frais generaux | D7: 7
A8: FLUX | B8: Realise | C8: Frais due diligence | D8: 8
D9: 9

Sheet Fiche entreprise p.1
B2: =+'Donnees figees'!B2 -> 0 | T2: 42825 | U2: =+HLOOKUP(T2,Capital!$1:$2,2,FALSE) -> 8
B4: Secteur d'activité : | C4: =+'Donnees figees'!B5 -> 0 | E4: - Nombre employés : | H4: =+INDEX(Impact!$E:$AE,Impact!$D$13,$U$2) -> 0 | I4: - Localisation : | J4: =+'Donnees figees'!B6 -> 0
B5: Année de création : | C5: =+'Donnees figees'!B4 -> 0 | D5: - Année investissement : | G5: =+'Donnees figees'!B8 -> 0 | I5: - Stade développement : | K5: =+'Donnees figees'!B7 -> 0
B6: Montant total investissement : | E6: =+'Fiche entreprise p.2'!C5 -> 0 | F6: - Pourcentage détention : | J6: =+INDEX(Capital!$E:$AE,Capital!$D$11,'Fiche entreprise p.1'!$U$2) -> 0
S10: Actionnaires | T10: Pourcentage
B19: ENTREPRENEUR
B28: RATIONNEL DE L'INVESTISSEMENT
B34: APPUI DE SINERGI | M34: ESG & IMPACT
B41: COMMENTAIRES ESG

Sheet Fiche entreprise p.2
B2: INVESTISSEMENT REALISE | H2: HISTORIQUE DE L'INVESTISSEMENT | Q2: =+'Fiche entreprise p.1'!T2 -> 42825 | R2: =+HLOOKUP(Q2,Capital!$1:$2,2,FALSE) -> 8
C4: Capital | D4: Prêt | E4: TOTAL
B5: Montant décaissé | C5: =+INDEX(Capital!$E:$AE,Capital!$D$17,$R$2) -> 0 | D5: =+INDEX(Pret!$E:$AE,Pret!$D$24,$R$2) -> 0 | E5: =+D5+C5 -> 0
B6: Montant engagé | C6: =+INDEX(Capital!$E:$AE,Capital!$D$14,$R$2) -> 0 | D6: =+INDEX(Pret!$E:$AE,Pret!$D$23,$R$2) -> 0 | E6: =+D6+C6 -> 0
B7: Restant à décaisser | C7: =+C6-C5 -> 0 | D7: =+D6-D5 -> 0 | E7: =+D7+C7 -> 0
B8: Revenus encaissés | C8: =+INDEX(Capital!$E:$AE,Capital!$D$19,$R$2)+INDEX(Capital!$E:$AE,Capital!$D$21,$R$2) -> 0 | D8: =+INDEX(Pret!$E:$AE,Pret!$D$26,$R$2) -> 0 | E8: =+D8+C8 -> 0
B9: Remboursements | C9: =+INDEX(Capital!$E:$AE,Capital!$D$18,$R$2) -> 0 | D9: =+INDEX(Pret!$E:$AE,Pret!$D$25,$R$2) -> 0 | E9: =+D9+C9 -> 0
B10: Arriérés | D10: =+INDEX(Pret!$E:$AE,Pret!$D$36,$R$2)+INDEX(Pret!$E:$AE,Pret!$D$37,$R$2) -> 0 | E10: =+D10+C10 -> 0
B11: Valorisation | C11: =+INDEX(Capital!$E:$AE,Capital!$D$16,$R$2) -> 0 | D11: =+INDEX(Pret!$E:$AE,Pret!$D$31,$R$2) -> 0 | E11: =+D11+C11 -> 0
B12: Multiple | C12: =+(C11+C8+C9)/C5 -> #DIV/0! | D12: =+(D11+D8+D9+D10)/D5 -> #DIV/0! | E12: =+(E11+E8+E9)/E5 -> #DIV/0!
H13: VALORISATION
B15: COMPTE DE RESULTAT | H15: Méthode de valorisation à l'acquisition | L15: =+'Donnees figees'!B9 -> 0
H16: Méthode de valorisation du capital à date | L16: Coût historique
C17: 42735 | D17: 42369 | E17: Variation | H17: Méthode de valorisation du prêt | L17: Coût historique
B18: Chiffre d'affaire | C18: =+INDEX(Performance!$E:$AE,Performance!$D$4,$R$18) -> 0 | D18: =+INDEX(Performance!$E:$AE,Performance!$D$4,$R$19) -> 0 | E18: =IF(OR(C18="N/A",D18="N/A",D18=0),"N/A",IF(OR(AND(C18>0,D18<0),AND(C18<0,D18<0)),-(C18-D18)/D18,(C18-D18)/D18)) -> N/A | Q18: =C17 -> 42735 | R18: =+HLOOKUP(Q18,Capital!$1:$2,2,FALSE) -> 7
B19: EBITDA | C19: =+INDEX(Performance!$E:$AE,Performance!$D$5,$R$18) -> 0 | D19: =+INDEX(Performance!$E:$AE,Performance!$D$5,$R$19) -> 0 | E19: =IF(OR(C19="N/A",D19="N/A",D19=0),"N/A",IF(OR(AND(C19>0,D19<0),AND(C19<0,D19<0)),-(C19-D19)/D19,(C19-D19)/D19)) -> N/A | Q19: =D17 -> 42369 | R19: =+HLOOKUP(Q19,Capital!$1:$2,2,FALSE) -> 3
B20: EBIT | C20: =+INDEX(Performance!$E:$AE,Performance!$D$6,$R$18) -> 0 | D20: =+INDEX(Performance!$E:$AE,Performance!$D$6,$R$19) -> 0 | E20: =IF(OR(C20="N/A",D20="N/A",D20=0),"N/A",IF(OR(AND(C20>0,D20<0),AND(C20<0,D20<0)),-(C20-D20)/D20,(C20-D20)/D20)) -> N/A | H20: Stratégie de sortie
B21: Résultat Net | C21: =+INDEX(Performance!$E:$AE,Performance!$D$7,$R$18) -> 0 | D21: =+INDEX(Performance!$E:$AE,Performance!$D$7,$R$19) -> 0 | E21: =IF(OR(C21="N/A",D21="N/A",D21=0),"N/A",IF(OR(AND(C21>0,D21<0),AND(C21<0,D21<0)),-(C21-D21)/D21,(C21-D21)/D21)) -> N/A
H22: Stratégie de sortie | J22: =+'Donnees figees'!B12 -> 0
H23: TRI attendu | J23: =+'Donnees figees'!B13 -> 0
B24: BILAN | H24: Année sortie | J24: =+'Donnees figees'!B10 -> 0
C26: =+C17 -> 42735 | D26: =+D17 -> 42369 | E26: Variation
B27: Immobilisations | C27: =+INDEX(Performance!$E:$AE,Performance!$D$10,$R$18) -> 0 | D27: =+INDEX(Performance!$E:$AE,Performance!$D$10,$R$19) -> 0 | E27: =IF(OR(C27="N/A",D27="N/A",D27=0),"N/A",IF(OR(AND(C27>0,D27<0),AND(C27<0,D27<0)),-(C27-D27)/D27,(C27-D27)/D27)) -> N/A | H27: PERFORMANCE ET EVENEMENTS DU TRIMESTRE
B28: Actif circulant | C28: =+INDEX(Performance!$E:$AE,Performance!$D$11,$R$18) -> 0 | D28: =+INDEX(Performance!$E:$AE,Performance!$D$11,$R$19) -> 0 | E28: =IF(OR(C28="N/A",D28="N/A",D28=0),"N/A",IF(OR(AND(C28>0,D28<0),AND(C28<0,D28<0)),-(C28-D28)/D28,(C28-D28)/D28)) -> N/A
B29: Trésorerie | C29: =+INDEX(Performance!$E:$AE,Performance!$D$12,$R$18) -> 0 | D29: =+INDEX(Performance!$E:$AE,Performance!$D$12,$R$19) -> 0 | E29: =IF(OR(C29="N/A",D29="N/A",D29=0),"N/A",IF(OR(AND(C29>0,D29<0),AND(C29<0,D29<0)),-(C29-D29)/D29,(C29-D29)/D29)) -> N/A
B30: TOTAL ACTIF | C30: =+SUM(C27:C29) -> 0 | D30: =+SUM(D27:D29) -> 0 | E30: =IF(OR(C30="N/A",D30="N/A",D30=0),"N/A",IF(OR(AND(C30>0,D30<0),AND(C30<0,D30<0)),-(C30-D30)/D30,(C30-D30)/D30)) -> N/A
B31: Fonds propres | C31: =+INDEX(Performance!$E:$AE,Performance!$D$14,$R$18) -> 0 | D31: =+INDEX(Performance!$E:$AE,Performance!$D$14,$R$19) -> 0 | E31: =IF(OR(C31="N/A",D31="N/A",D31=0),"N/A",IF(OR(AND(C31>0,D31<0),AND(C31<0,D31<0)),-(C31-D31)/D31,(C31-D31)/D31)) -> N/A
B32: Dettes long terme | C32: =+INDEX(Performance!$E:$AE,Performance!$D$15,$R$18) -> 0 | D32: =+INDEX(Performance!$E:$AE,Performance!$D$15,$R$19) -> 0 | E32: =IF(OR(C32="N/A",D32="N/A",D32=0),"N/A",IF(OR(AND(C32>0,D32<0),AND(C32<0,D32<0)),-(C32-D32)/D32,(C32-D32)/D32)) -> N/A
B33: Dettes court terme | C33: =+INDEX(Performance!$E:$AE,Performance!$D$16,$R$18) -> 0 | D33: =+INDEX(Performance!$E:$AE,Performance!$D$16,$R$19) -> 0 | E33: =IF(OR(C33="N/A",D33="N/A",D33=0),"N/A",IF(OR(AND(C33>0,D33<0),AND(C33<0,D33<0)),-(C33-D33)/D33,(C33-D33)/D33)) -> N/A
B34: TOTAL PASSIF | C34: =+SUM(C31:C33) -> 0 | D34: =+SUM(D31:D33) -> 0 | E34: =IF(OR(C34="N/A",D34="N/A",D34=0),"N/A",IF(OR(AND(C34>0,D34<0),AND(C34<0,D34<0)),-(C34-D34)/D34,(C34-D34)/D34)) -> N/A
B37: INDICATEURS DE PERFORMANCE
C39: =+C26 -> 42735 | D39: =+D26 -> 42369
B40: EBITDA / CA | C40: =+C19/C18 -> #DIV/0! | D40: =+D19/D18 -> #DIV/0!
B41: Marge nette | C41: =+C21/C18 -> #DIV/0! | D41: =+D21/D18 -> #DIV/0!
B42: ROE | C42: =+C21/C31 -> #DIV/0! | D42: =+D21/D31 -> #DIV/0!
B43: Fonds propres / passif | C43: =+C31/C34 -> #DIV/0! | D43: =+D31/D34 -> #DIV/0!
